[2025-03-16T03:50:39.268+0000] {local_task_job_runner.py:123} INFO - ::group::Pre task execution logs
[2025-03-16T03:50:39.284+0000] {taskinstance.py:2613} INFO - Dependencies all met for dep_context=non-requeueable deps ti=<TaskInstance: data_pipeline.silver_layer_group.transform_data scheduled__2025-03-16T02:00:00+00:00 [queued]>
[2025-03-16T03:50:39.292+0000] {taskinstance.py:2613} INFO - Dependencies all met for dep_context=requeueable deps ti=<TaskInstance: data_pipeline.silver_layer_group.transform_data scheduled__2025-03-16T02:00:00+00:00 [queued]>
[2025-03-16T03:50:39.292+0000] {taskinstance.py:2866} INFO - Starting attempt 1 of 4
[2025-03-16T03:50:39.304+0000] {taskinstance.py:2889} INFO - Executing <Task(_PythonDecoratedOperator): silver_layer_group.transform_data> on 2025-03-16 02:00:00+00:00
[2025-03-16T03:50:39.313+0000] {standard_task_runner.py:72} INFO - Started process 406 to run task
[2025-03-16T03:50:39.317+0000] {standard_task_runner.py:104} INFO - Running: ['***', 'tasks', 'run', 'data_pipeline', 'silver_layer_group.transform_data', 'scheduled__2025-03-16T02:00:00+00:00', '--job-id', '112', '--raw', '--subdir', 'DAGS_FOLDER/data_pipeline.py', '--cfg-path', '/tmp/tmprzok2hk3']
[2025-03-16T03:50:39.318+0000] {standard_task_runner.py:105} INFO - Job 112: Subtask silver_layer_group.transform_data
[2025-03-16T03:50:39.375+0000] {task_command.py:467} INFO - Running <TaskInstance: data_pipeline.silver_layer_group.transform_data scheduled__2025-03-16T02:00:00+00:00 [running]> on host c891f3a5df31
[2025-03-16T03:50:39.471+0000] {taskinstance.py:3132} INFO - Exporting env vars: AIRFLOW_CTX_DAG_OWNER='***' AIRFLOW_CTX_DAG_ID='data_pipeline' AIRFLOW_CTX_TASK_ID='silver_layer_group.transform_data' AIRFLOW_CTX_EXECUTION_DATE='2025-03-16T02:00:00+00:00' AIRFLOW_CTX_TRY_NUMBER='1' AIRFLOW_CTX_DAG_RUN_ID='scheduled__2025-03-16T02:00:00+00:00'
[2025-03-16T03:50:39.473+0000] {taskinstance.py:731} INFO - ::endgroup::
[2025-03-16T03:50:39.477+0000] {log.py:232} WARNING - 2025-03-16 03:50:39.476 | INFO     | data_pipeline.silver.transform_data:transform_data:183 - Starting data transformation
[2025-03-16T03:50:39.484+0000] {log.py:232} WARNING - 2025-03-16 03:50:39.484 | DEBUG    | data_pipeline.silver.transform_data:transform_data:197 - Initial DataFrame columns: ['VendorID', 'lpep_pickup_datetime', 'lpep_dropoff_datetime', 'store_and_fwd_flag', 'RatecodeID', 'PULocationID', 'DOLocationID', 'passenger_count', 'trip_distance', 'fare_amount', 'extra', 'mta_tax', 'tip_amount', 'tolls_amount', 'ehail_fee', 'improvement_surcharge', 'total_amount', 'payment_type', 'trip_type', 'congestion_surcharge', 'is_dummy', 'record_hash', 'processed_date', 'processing_pipeline', 'valid']
[2025-03-16T03:50:39.485+0000] {log.py:232} WARNING - 2025-03-16 03:50:39.485 | DEBUG    | data_pipeline.silver.transform_data:transform_data:198 - DataFrame shape: (1, 25)
[2025-03-16T03:50:39.491+0000] {log.py:232} WARNING - 2025-03-16 03:50:39.491 | INFO     | data_pipeline.silver.transform_data:check_duplicates:160 - Removed 0 duplicate records
[2025-03-16T03:50:39.492+0000] {log.py:232} WARNING - 2025-03-16 03:50:39.492 | DEBUG    | data_pipeline.silver.transform_data:transform_timestamps:64 - Transforming timestamps
[2025-03-16T03:50:39.492+0000] {log.py:232} WARNING - 2025-03-16 03:50:39.492 | ERROR    | data_pipeline.silver.transform_data:transform_data:209 - Failed during transformation: 'tpep_pickup_datetime'
[2025-03-16T03:50:39.493+0000] {log.py:232} WARNING - 2025-03-16 03:50:39.493 | ERROR    | data_pipeline.silver.transform_data:transform_data:241 - Failed to transform data: 'tpep_pickup_datetime'
[2025-03-16T03:50:39.493+0000] {taskinstance.py:3311} ERROR - Task failed with exception
Traceback (most recent call last):
  File "/home/airflow/.local/lib/python3.9/site-packages/pandas/core/indexes/base.py", line 3361, in get_loc
    return self._engine.get_loc(casted_key)
  File "pandas/_libs/index.pyx", line 76, in pandas._libs.index.IndexEngine.get_loc
  File "pandas/_libs/index.pyx", line 108, in pandas._libs.index.IndexEngine.get_loc
  File "pandas/_libs/hashtable_class_helper.pxi", line 5198, in pandas._libs.hashtable.PyObjectHashTable.get_item
  File "pandas/_libs/hashtable_class_helper.pxi", line 5206, in pandas._libs.hashtable.PyObjectHashTable.get_item
KeyError: 'tpep_pickup_datetime'

The above exception was the direct cause of the following exception:

Traceback (most recent call last):
  File "/opt/airflow/dags/data_pipeline/silver/transform_data.py", line 205, in transform_data
    df = transform_timestamps(df)
  File "/opt/airflow/dags/data_pipeline/silver/transform_data.py", line 66, in transform_timestamps
    df["pickup_datetime"] = pd.to_datetime(df["tpep_pickup_datetime"])
  File "/home/airflow/.local/lib/python3.9/site-packages/pandas/core/frame.py", line 3455, in __getitem__
    indexer = self.columns.get_loc(key)
  File "/home/airflow/.local/lib/python3.9/site-packages/pandas/core/indexes/base.py", line 3363, in get_loc
    raise KeyError(key) from err
KeyError: 'tpep_pickup_datetime'

During handling of the above exception, another exception occurred:

Traceback (most recent call last):
  File "/home/airflow/.local/lib/python3.9/site-packages/airflow/models/taskinstance.py", line 762, in _execute_task
    result = _execute_callable(context=context, **execute_callable_kwargs)
  File "/home/airflow/.local/lib/python3.9/site-packages/airflow/models/taskinstance.py", line 733, in _execute_callable
    return ExecutionCallableRunner(
  File "/home/airflow/.local/lib/python3.9/site-packages/airflow/utils/operator_helpers.py", line 252, in run
    return self.func(*args, **kwargs)
  File "/home/airflow/.local/lib/python3.9/site-packages/airflow/models/baseoperator.py", line 417, in wrapper
    return func(self, *args, **kwargs)
  File "/home/airflow/.local/lib/python3.9/site-packages/airflow/decorators/base.py", line 266, in execute
    return_value = super().execute(context)
  File "/home/airflow/.local/lib/python3.9/site-packages/airflow/models/baseoperator.py", line 417, in wrapper
    return func(self, *args, **kwargs)
  File "/home/airflow/.local/lib/python3.9/site-packages/airflow/operators/python.py", line 238, in execute
    return_value = self.execute_callable()
  File "/home/airflow/.local/lib/python3.9/site-packages/airflow/operators/python.py", line 256, in execute_callable
    return runner.run(*self.op_args, **self.op_kwargs)
  File "/home/airflow/.local/lib/python3.9/site-packages/airflow/utils/operator_helpers.py", line 252, in run
    return self.func(*args, **kwargs)
  File "/opt/airflow/dags/data_pipeline/silver/transform_data.py", line 242, in transform_data
    raise Exception(f"Failed to transform data: {str(e)}")
Exception: Failed to transform data: 'tpep_pickup_datetime'
[2025-03-16T03:50:39.514+0000] {taskinstance.py:1225} INFO - Marking task as UP_FOR_RETRY. dag_id=data_pipeline, task_id=silver_layer_group.transform_data, run_id=scheduled__2025-03-16T02:00:00+00:00, execution_date=20250316T020000, start_date=20250316T035039, end_date=20250316T035039
[2025-03-16T03:50:39.530+0000] {taskinstance.py:340} INFO - ::group::Post task execution logs
[2025-03-16T03:50:39.531+0000] {standard_task_runner.py:124} ERROR - Failed to execute job 112 for task silver_layer_group.transform_data (Failed to transform data: 'tpep_pickup_datetime'; 406)
Traceback (most recent call last):
  File "/home/airflow/.local/lib/python3.9/site-packages/pandas/core/indexes/base.py", line 3361, in get_loc
    return self._engine.get_loc(casted_key)
  File "pandas/_libs/index.pyx", line 76, in pandas._libs.index.IndexEngine.get_loc
  File "pandas/_libs/index.pyx", line 108, in pandas._libs.index.IndexEngine.get_loc
  File "pandas/_libs/hashtable_class_helper.pxi", line 5198, in pandas._libs.hashtable.PyObjectHashTable.get_item
  File "pandas/_libs/hashtable_class_helper.pxi", line 5206, in pandas._libs.hashtable.PyObjectHashTable.get_item
KeyError: 'tpep_pickup_datetime'

The above exception was the direct cause of the following exception:

Traceback (most recent call last):
  File "/opt/airflow/dags/data_pipeline/silver/transform_data.py", line 205, in transform_data
    df = transform_timestamps(df)
  File "/opt/airflow/dags/data_pipeline/silver/transform_data.py", line 66, in transform_timestamps
    df["pickup_datetime"] = pd.to_datetime(df["tpep_pickup_datetime"])
  File "/home/airflow/.local/lib/python3.9/site-packages/pandas/core/frame.py", line 3455, in __getitem__
    indexer = self.columns.get_loc(key)
  File "/home/airflow/.local/lib/python3.9/site-packages/pandas/core/indexes/base.py", line 3363, in get_loc
    raise KeyError(key) from err
KeyError: 'tpep_pickup_datetime'

During handling of the above exception, another exception occurred:

Traceback (most recent call last):
  File "/home/airflow/.local/lib/python3.9/site-packages/airflow/task/task_runner/standard_task_runner.py", line 117, in _start_by_fork
    ret = args.func(args, dag=self.dag)
  File "/home/airflow/.local/lib/python3.9/site-packages/airflow/cli/cli_config.py", line 49, in command
    return func(*args, **kwargs)
  File "/home/airflow/.local/lib/python3.9/site-packages/airflow/utils/cli.py", line 116, in wrapper
    return f(*args, **kwargs)
  File "/home/airflow/.local/lib/python3.9/site-packages/airflow/cli/commands/task_command.py", line 483, in task_run
    task_return_code = _run_task_by_selected_method(args, _dag, ti)
  File "/home/airflow/.local/lib/python3.9/site-packages/airflow/cli/commands/task_command.py", line 256, in _run_task_by_selected_method
    return _run_raw_task(args, ti)
  File "/home/airflow/.local/lib/python3.9/site-packages/airflow/cli/commands/task_command.py", line 341, in _run_raw_task
    return ti._run_raw_task(
  File "/home/airflow/.local/lib/python3.9/site-packages/airflow/utils/session.py", line 97, in wrapper
    return func(*args, session=session, **kwargs)
  File "/home/airflow/.local/lib/python3.9/site-packages/airflow/models/taskinstance.py", line 3005, in _run_raw_task
    return _run_raw_task(
  File "/home/airflow/.local/lib/python3.9/site-packages/airflow/models/taskinstance.py", line 273, in _run_raw_task
    TaskInstance._execute_task_with_callbacks(
  File "/home/airflow/.local/lib/python3.9/site-packages/airflow/models/taskinstance.py", line 3159, in _execute_task_with_callbacks
    result = self._execute_task(context, task_orig)
  File "/home/airflow/.local/lib/python3.9/site-packages/airflow/models/taskinstance.py", line 3183, in _execute_task
    return _execute_task(self, context, task_orig)
  File "/home/airflow/.local/lib/python3.9/site-packages/airflow/models/taskinstance.py", line 762, in _execute_task
    result = _execute_callable(context=context, **execute_callable_kwargs)
  File "/home/airflow/.local/lib/python3.9/site-packages/airflow/models/taskinstance.py", line 733, in _execute_callable
    return ExecutionCallableRunner(
  File "/home/airflow/.local/lib/python3.9/site-packages/airflow/utils/operator_helpers.py", line 252, in run
    return self.func(*args, **kwargs)
  File "/home/airflow/.local/lib/python3.9/site-packages/airflow/models/baseoperator.py", line 417, in wrapper
    return func(self, *args, **kwargs)
  File "/home/airflow/.local/lib/python3.9/site-packages/airflow/decorators/base.py", line 266, in execute
    return_value = super().execute(context)
  File "/home/airflow/.local/lib/python3.9/site-packages/airflow/models/baseoperator.py", line 417, in wrapper
    return func(self, *args, **kwargs)
  File "/home/airflow/.local/lib/python3.9/site-packages/airflow/operators/python.py", line 238, in execute
    return_value = self.execute_callable()
  File "/home/airflow/.local/lib/python3.9/site-packages/airflow/operators/python.py", line 256, in execute_callable
    return runner.run(*self.op_args, **self.op_kwargs)
  File "/home/airflow/.local/lib/python3.9/site-packages/airflow/utils/operator_helpers.py", line 252, in run
    return self.func(*args, **kwargs)
  File "/opt/airflow/dags/data_pipeline/silver/transform_data.py", line 242, in transform_data
    raise Exception(f"Failed to transform data: {str(e)}")
Exception: Failed to transform data: 'tpep_pickup_datetime'
[2025-03-16T03:50:39.547+0000] {local_task_job_runner.py:266} INFO - Task exited with return code 1
[2025-03-16T03:50:39.567+0000] {taskinstance.py:3895} INFO - 0 downstream tasks scheduled from follow-on schedule check
[2025-03-16T03:50:39.570+0000] {local_task_job_runner.py:245} INFO - ::endgroup::
