[2025-03-16T03:53:41.921+0000] {local_task_job_runner.py:123} INFO - ::group::Pre task execution logs
[2025-03-16T03:53:41.938+0000] {taskinstance.py:2613} INFO - Dependencies all met for dep_context=non-requeueable deps ti=<TaskInstance: data_pipeline.gold_layer_group.load_dimensions_and_facts manual__2025-03-16T03:52:42.716254+00:00 [queued]>
[2025-03-16T03:53:41.946+0000] {taskinstance.py:2613} INFO - Dependencies all met for dep_context=requeueable deps ti=<TaskInstance: data_pipeline.gold_layer_group.load_dimensions_and_facts manual__2025-03-16T03:52:42.716254+00:00 [queued]>
[2025-03-16T03:53:41.946+0000] {taskinstance.py:2866} INFO - Starting attempt 3 of 6
[2025-03-16T03:53:41.958+0000] {taskinstance.py:2889} INFO - Executing <Task(_PythonDecoratedOperator): gold_layer_group.load_dimensions_and_facts> on 2025-03-16 03:52:42.716254+00:00
[2025-03-16T03:53:41.966+0000] {standard_task_runner.py:72} INFO - Started process 1000 to run task
[2025-03-16T03:53:41.970+0000] {standard_task_runner.py:104} INFO - Running: ['***', 'tasks', 'run', 'data_pipeline', 'gold_layer_group.load_dimensions_and_facts', 'manual__2025-03-16T03:52:42.716254+00:00', '--job-id', '140', '--raw', '--subdir', 'DAGS_FOLDER/data_pipeline.py', '--cfg-path', '/tmp/tmpwq5lod_z']
[2025-03-16T03:53:41.972+0000] {standard_task_runner.py:105} INFO - Job 140: Subtask gold_layer_group.load_dimensions_and_facts
[2025-03-16T03:53:42.019+0000] {task_command.py:467} INFO - Running <TaskInstance: data_pipeline.gold_layer_group.load_dimensions_and_facts manual__2025-03-16T03:52:42.716254+00:00 [running]> on host c891f3a5df31
[2025-03-16T03:53:42.096+0000] {taskinstance.py:3132} INFO - Exporting env vars: AIRFLOW_CTX_DAG_OWNER='***' AIRFLOW_CTX_DAG_ID='data_pipeline' AIRFLOW_CTX_TASK_ID='gold_layer_group.load_dimensions_and_facts' AIRFLOW_CTX_EXECUTION_DATE='2025-03-16T03:52:42.716254+00:00' AIRFLOW_CTX_TRY_NUMBER='3' AIRFLOW_CTX_DAG_RUN_ID='manual__2025-03-16T03:52:42.716254+00:00'
[2025-03-16T03:53:42.097+0000] {taskinstance.py:731} INFO - ::endgroup::
[2025-03-16T03:53:42.100+0000] {log.py:232} WARNING - 2025-03-16 03:53:42.099 | INFO     | data_pipeline.gold.load_to_dwh:load_dimensions_and_facts:172 - Loading dimensions and facts into Data Warehouse
[2025-03-16T03:53:42.102+0000] {crypto.py:82} WARNING - empty cryptography key - values will not be stored encrypted.
[2025-03-16T03:53:42.103+0000] {base.py:84} INFO - Retrieving connection 'postgres_***'
[2025-03-16T03:53:42.107+0000] {sql.py:624} INFO - Running statement: CREATE SCHEMA IF NOT EXISTS ***;, parameters: None
[2025-03-16T03:53:42.108+0000] {log.py:232} WARNING - 2025-03-16 03:53:42.107 | INFO     | data_pipeline.gold.load_to_***:create_dim_vendor:23 - Creating vendor dimension table
[2025-03-16T03:53:42.109+0000] {log.py:232} WARNING - 2025-03-16 03:53:42.109 | ERROR    | data_pipeline.gold.load_to_***:load_dimensions_and_facts:220 - Failed to load dimensional model: "None of [Index(['VendorID'], dtype='object')] are in the [columns]"
[2025-03-16T03:53:42.110+0000] {taskinstance.py:3311} ERROR - Task failed with exception
Traceback (most recent call last):
  File "/opt/airflow/dags/data_pipeline/gold/load_to_dwh.py", line 182, in load_dimensions_and_facts
    "dwh.dim_vendor": create_dim_vendor(df),
  File "/opt/airflow/dags/data_pipeline/gold/load_to_dwh.py", line 24, in create_dim_vendor
    dim_vendor = df[["VendorID"]].copy()
  File "/home/airflow/.local/lib/python3.9/site-packages/pandas/core/frame.py", line 3461, in __getitem__
    indexer = self.loc._get_listlike_indexer(key, axis=1)[1]
  File "/home/airflow/.local/lib/python3.9/site-packages/pandas/core/indexing.py", line 1314, in _get_listlike_indexer
    self._validate_read_indexer(keyarr, indexer, axis)
  File "/home/airflow/.local/lib/python3.9/site-packages/pandas/core/indexing.py", line 1374, in _validate_read_indexer
    raise KeyError(f"None of [{key}] are in the [{axis_name}]")
KeyError: "None of [Index(['VendorID'], dtype='object')] are in the [columns]"

During handling of the above exception, another exception occurred:

Traceback (most recent call last):
  File "/home/airflow/.local/lib/python3.9/site-packages/airflow/models/taskinstance.py", line 762, in _execute_task
    result = _execute_callable(context=context, **execute_callable_kwargs)
  File "/home/airflow/.local/lib/python3.9/site-packages/airflow/models/taskinstance.py", line 733, in _execute_callable
    return ExecutionCallableRunner(
  File "/home/airflow/.local/lib/python3.9/site-packages/airflow/utils/operator_helpers.py", line 252, in run
    return self.func(*args, **kwargs)
  File "/home/airflow/.local/lib/python3.9/site-packages/airflow/models/baseoperator.py", line 417, in wrapper
    return func(self, *args, **kwargs)
  File "/home/airflow/.local/lib/python3.9/site-packages/airflow/decorators/base.py", line 266, in execute
    return_value = super().execute(context)
  File "/home/airflow/.local/lib/python3.9/site-packages/airflow/models/baseoperator.py", line 417, in wrapper
    return func(self, *args, **kwargs)
  File "/home/airflow/.local/lib/python3.9/site-packages/airflow/operators/python.py", line 238, in execute
    return_value = self.execute_callable()
  File "/home/airflow/.local/lib/python3.9/site-packages/airflow/operators/python.py", line 256, in execute_callable
    return runner.run(*self.op_args, **self.op_kwargs)
  File "/home/airflow/.local/lib/python3.9/site-packages/airflow/utils/operator_helpers.py", line 252, in run
    return self.func(*args, **kwargs)
  File "/opt/airflow/dags/data_pipeline/gold/load_to_dwh.py", line 221, in load_dimensions_and_facts
    raise Exception(f"Failed to load dimensional model: {str(e)}")
Exception: Failed to load dimensional model: "None of [Index(['VendorID'], dtype='object')] are in the [columns]"
[2025-03-16T03:53:42.122+0000] {taskinstance.py:1225} INFO - Marking task as UP_FOR_RETRY. dag_id=data_pipeline, task_id=gold_layer_group.load_dimensions_and_facts, run_id=manual__2025-03-16T03:52:42.716254+00:00, execution_date=20250316T035242, start_date=20250316T035341, end_date=20250316T035342
[2025-03-16T03:53:42.136+0000] {taskinstance.py:340} INFO - ::group::Post task execution logs
[2025-03-16T03:53:42.137+0000] {standard_task_runner.py:124} ERROR - Failed to execute job 140 for task gold_layer_group.load_dimensions_and_facts (Failed to load dimensional model: "None of [Index(['VendorID'], dtype='object')] are in the [columns]"; 1000)
Traceback (most recent call last):
  File "/opt/airflow/dags/data_pipeline/gold/load_to_dwh.py", line 182, in load_dimensions_and_facts
    "dwh.dim_vendor": create_dim_vendor(df),
  File "/opt/airflow/dags/data_pipeline/gold/load_to_dwh.py", line 24, in create_dim_vendor
    dim_vendor = df[["VendorID"]].copy()
  File "/home/airflow/.local/lib/python3.9/site-packages/pandas/core/frame.py", line 3461, in __getitem__
    indexer = self.loc._get_listlike_indexer(key, axis=1)[1]
  File "/home/airflow/.local/lib/python3.9/site-packages/pandas/core/indexing.py", line 1314, in _get_listlike_indexer
    self._validate_read_indexer(keyarr, indexer, axis)
  File "/home/airflow/.local/lib/python3.9/site-packages/pandas/core/indexing.py", line 1374, in _validate_read_indexer
    raise KeyError(f"None of [{key}] are in the [{axis_name}]")
KeyError: "None of [Index(['VendorID'], dtype='object')] are in the [columns]"

During handling of the above exception, another exception occurred:

Traceback (most recent call last):
  File "/home/airflow/.local/lib/python3.9/site-packages/airflow/task/task_runner/standard_task_runner.py", line 117, in _start_by_fork
    ret = args.func(args, dag=self.dag)
  File "/home/airflow/.local/lib/python3.9/site-packages/airflow/cli/cli_config.py", line 49, in command
    return func(*args, **kwargs)
  File "/home/airflow/.local/lib/python3.9/site-packages/airflow/utils/cli.py", line 116, in wrapper
    return f(*args, **kwargs)
  File "/home/airflow/.local/lib/python3.9/site-packages/airflow/cli/commands/task_command.py", line 483, in task_run
    task_return_code = _run_task_by_selected_method(args, _dag, ti)
  File "/home/airflow/.local/lib/python3.9/site-packages/airflow/cli/commands/task_command.py", line 256, in _run_task_by_selected_method
    return _run_raw_task(args, ti)
  File "/home/airflow/.local/lib/python3.9/site-packages/airflow/cli/commands/task_command.py", line 341, in _run_raw_task
    return ti._run_raw_task(
  File "/home/airflow/.local/lib/python3.9/site-packages/airflow/utils/session.py", line 97, in wrapper
    return func(*args, session=session, **kwargs)
  File "/home/airflow/.local/lib/python3.9/site-packages/airflow/models/taskinstance.py", line 3005, in _run_raw_task
    return _run_raw_task(
  File "/home/airflow/.local/lib/python3.9/site-packages/airflow/models/taskinstance.py", line 273, in _run_raw_task
    TaskInstance._execute_task_with_callbacks(
  File "/home/airflow/.local/lib/python3.9/site-packages/airflow/models/taskinstance.py", line 3159, in _execute_task_with_callbacks
    result = self._execute_task(context, task_orig)
  File "/home/airflow/.local/lib/python3.9/site-packages/airflow/models/taskinstance.py", line 3183, in _execute_task
    return _execute_task(self, context, task_orig)
  File "/home/airflow/.local/lib/python3.9/site-packages/airflow/models/taskinstance.py", line 762, in _execute_task
    result = _execute_callable(context=context, **execute_callable_kwargs)
  File "/home/airflow/.local/lib/python3.9/site-packages/airflow/models/taskinstance.py", line 733, in _execute_callable
    return ExecutionCallableRunner(
  File "/home/airflow/.local/lib/python3.9/site-packages/airflow/utils/operator_helpers.py", line 252, in run
    return self.func(*args, **kwargs)
  File "/home/airflow/.local/lib/python3.9/site-packages/airflow/models/baseoperator.py", line 417, in wrapper
    return func(self, *args, **kwargs)
  File "/home/airflow/.local/lib/python3.9/site-packages/airflow/decorators/base.py", line 266, in execute
    return_value = super().execute(context)
  File "/home/airflow/.local/lib/python3.9/site-packages/airflow/models/baseoperator.py", line 417, in wrapper
    return func(self, *args, **kwargs)
  File "/home/airflow/.local/lib/python3.9/site-packages/airflow/operators/python.py", line 238, in execute
    return_value = self.execute_callable()
  File "/home/airflow/.local/lib/python3.9/site-packages/airflow/operators/python.py", line 256, in execute_callable
    return runner.run(*self.op_args, **self.op_kwargs)
  File "/home/airflow/.local/lib/python3.9/site-packages/airflow/utils/operator_helpers.py", line 252, in run
    return self.func(*args, **kwargs)
  File "/opt/airflow/dags/data_pipeline/gold/load_to_dwh.py", line 221, in load_dimensions_and_facts
    raise Exception(f"Failed to load dimensional model: {str(e)}")
Exception: Failed to load dimensional model: "None of [Index(['VendorID'], dtype='object')] are in the [columns]"
[2025-03-16T03:53:42.148+0000] {local_task_job_runner.py:266} INFO - Task exited with return code 1
[2025-03-16T03:53:42.168+0000] {taskinstance.py:3895} INFO - 0 downstream tasks scheduled from follow-on schedule check
[2025-03-16T03:53:42.170+0000] {local_task_job_runner.py:245} INFO - ::endgroup::
